Workbook

Sheet OB-R Top Level BOM
B2: OB-R BOM - TOP LEVEL | G2: OB-R BOM - TOP LEVEL DIY
B3: PART | C3: QTY | D3: PRICE | E3: TOTAL | G3: PART | H3: QTY | I3: PRICE | J3: TOTAL | K3: 3250 | L3: 20 | M3: 8 voice | N3: =L3*K3 -> 65000
B4: Mainboard | C4: 1 | D4: ='OB-R Mainboard'!#REF! -> #REF! | E4: =D4*C4 -> #REF! | G4: Mainboard | H4: 1 | I4: ='OB-R Mainboard'!#REF! -> #REF! | J4: =I4*H4 -> #REF! | K4: 1995 | L4: 10 | M4: 4 voice | N4: =L4*K4 -> 19950
B5: Voice Mobo | C5: 1 | D5: ='OB-R Voice Mobo'!L35 -> 137.48553 | E5: =D5*C5 -> 137.48553 | G5: Voice Mobo | H5: 1 | I5: ='OB-R Voice Mobo'!J35 -> 97.552 | J5: =I5*H5 -> 97.552 | N5: =SUM(N3:N4) -> 84950
B6: Voice Card | C6: 8 | D6: ='OB-R Voice Card RevA'!M83 -> 73.3697 | E6: =D6*C6 -> 586.9576 | G6: Voice Card | H6: 1 | I6: ='OB-R Voice Card RevA'!K83 -> 923.52 | J6: =I6*H6 -> 923.52 | L6: 30
B7: Panelboard | C7: 1 | D7: ='OB-R Panel'!L19 -> 64.1 | E7: 150 | G7: Panelboard | H7: 1 | I7: ='OB-R Panel'!J19 -> 73.993 | J7: 150
B8: DAC Board | C8: 1 | D8: ='OB-R DAC Board'!J22 -> 38.536 | E8: =D8*C8 -> 38.536 | G8: DAC Board | H8: 1 | I8: ='OB-R DAC Board'!O22 -> 0 | J8: =I8*H8 -> 0
B9: IO Board | C9: 1 | D9: ='OB-R IO Board'!J20 -> 9.63419 | E9: =D9*C9 -> 9.63419 | G9: IO Board | H9: 1 | I9: ='OB-R IO Board'!O20 -> 0 | J9: =I9*H9 -> 0
B10: RT1062 | C10: 1 | D10: 22 | E10: =D10*C10 -> 22 | G10: RT1062 | H10: 1 | I10: 0 | J10: =I10*H10 -> 0
B11: Enclosure | C11: 1 | D11: ='OB-R Enclosure'!I7 -> 188.81 | E11: =D11*C11 -> 188.81 | G11: Enclosure | H11: 1 | I11: ='OB-R Enclosure'!N7 -> 0 | J11: =I11*H11 -> 0
B12: Hardware | C12: 1 | D12: =Hardware!#REF! -> #REF! | E12: =D12*C12 -> #REF! | G12: Hardware | H12: 1 | I12: =Hardware!#REF! -> #REF! | J12: =I12*H12 -> #REF!
B13: Packaging | C13: 1 | D13: =Packaging!I8 -> 9.1 | E13: =D13*C13 -> 9.1 | G13: Packaging | H13: 1 | I13: =Packaging!N8 -> 0 | J13: =I13*H13 -> 0
E14: =SUM(E4:E13) -> #REF! | I14: =SUM(I4:I13) -> #REF!
E15: =E4+E5+E7+E8+E9+E11+E12+E13 -> #REF!
E16: =30*E15 -> #REF! | F16: needed towards parts and assemblies
E17: =85000-E16 -> #REF! | F17: profit
B21: LISTED
B22: H3000 | C22: 1500
B23: SRX815 | C23: 1500
B24: Active 20 | C24: 700
B25: SH-101 | C25: 1500
B26: dbx 4800 | C26: 2000
C27: =SUM(C22:C26) -> 7200
B30: Kit
B31: DAC Board | C31: ='OB-R DAC Board'!J22 -> 38.536
B32: Voice Card | C32: ='OB-R Voice Card RevA'!M84*8 -> 40.32
B33: Mainboard | C33: ='OB-R Mainboard'!#REF! -> #REF!
B34: Mcu Module | C34: 28
B35: Voice Mobo | C35: ='OB-R Voice Mobo'!L36 -> 16.68
B36: Panelboard | C36: ='OB-R Panel'!L20 -> 21.7
B37: IO Board | C37: ='OB-R IO Board'!J20 -> 9.63419
B38: Enclosure | C38: ='OB-R Enclosure'!I7 -> 188.81
B39: Hardware | C39: =E12 -> #REF!
B40: Packaging | C40: 7
C41: =SUM(C31:C40) -> #REF! | D41: 382
C42: =C41*3 -> #REF! | D42: =D41*3 -> 1146
C43: 999

Sheet OB-R Mainboard
C1: ` | D1: v0.90 12/23/2019
D2: ABSTRAKT INSTRUMENTS VS-1 DIY BOM
D3: MAINBOARD
B4: ITEM | D4: DESCRIPTION | E4: DESIGNATOR | F4: QTY | G4: MANUFACTURER | H4: VENDOR | I4: PART NUMBER
B5: 3 | D5: Resistor 1k | E5: R2, R12, R14, R16, R19, R28, R31, R32, R150, R167 | F5: 10 | G5: Stackpole | H5: Digikey | I5: RNF18FTD1K00
B6: 4 | D6: Resistor 3.3k | E6: R99, R102, R105, R108, R111, R115, R119, R123 | F6: 8 | G6: Stackpole | H6: Digikey | I6: RNF18FTD3K30
B7: 6 | D7: Resistor 4.7k | E7: R9, R26, R187 | F7: 3 | G7: Stackpole | H7: Digikey | I7: RNF18FTD4K70
B8: 7 | D8: Resistor 5.11k 1% | E8: R5, R22 | F8: 2 | G8: Stackpole | H8: Digikey | I8: RNF18FTD5K11
B9: 8 | D9: Resistor 10k | E9: R76, R80, R88, R92, R188 | F9: 5 | G9: Stackpole | H9: Digikey | I9: RNF18FTD10K0
B10: 12 | D10: Resistor 15k | E10: R3, R4, R11, R15, R20, R21, R29, R34, R97, R100, R103, R106, R109, R113, R117, R121 | F10: 16 | G10: Stackpole | H10: Digikey | I10: RNF18FTD15K0
B11: 15 | D11: Resistor 20k 1% | E11: R7, R24 | F11: 1 | G11: Stackpole | H11: Digikey | I11: RNF18FTD20K0
B12: 16 | D12: Resistor 22.1k | E12: R112, R116, R120, R124, R151, R168 | F12: 6 | G12: Stackpole | H12: Digikey | I12: RNF18FTD22K1
B13: 17 | D13: Resistor 33k | E13: R75, R79, R87, R91, R185, R186 | F13: 6 | G13: Stackpole | H13: Digikey | I13: RNF18FTD33K0
B14: 20 | D14: Resistor 68k | E14: R131, R136, R152, R169 | F14: 4 | G14: Stackpole | H14: Digikey | I14: RNF18FTD68K0
B15: 21 | D15: Resistor 75k | E15: R148, R165 | F15: 2 | G15: Stackpole | H15: Digikey | I15: RNF18FTD75K0
B16: 22 | D16: Resistor 100k | E16: R1, R10, R13, R17, R18, R27, R30, R33, R35, R36, R37, R38, R39, R40, R41, R42, R43, R44, R45, R46, R47, R48, R49, R50, R51, R52, R53, R56, R57, R58, R59, R60, R61, R62, R63, R64, R65, R68, R69, R70, R71, R72, R73, R74, R78, R81, R82, R83, R85, R86, R90, R93, R94, R95, R98, R101, R104, R107, R110, R114, R118, R122, R129, R138, R142, R143, R144, R145, R159, R160, R161, R162, R163, R189 | F16: 74 | G16: Stackpole | H16: Digikey | I16: RNF18FTD100K
... B29: 38 | D29: Capacitor 470pF | E29: C1, C5, C10, C12, C17, C21, C25, C28 | F29: 8 | G29: TDK | H29: Digikey | I29: FG28C0G1H471JNT06
D30: Capacitor 1nF | E30: C42, C52 | F30: 2 | G30: Panasonic | H30: Digikey | I30: ECQ-E12102J
B31: 43 | D31: Capacitor 0.01uF | E31: C75, C76 | F31: 2 | G31: Panasonic | H31: Digikey | I31: ECQ-E2103J
B32: 39 | D32: Capacitor 0.022uF | E32: C2, C6, C9, C13, C18, C22, C26, C29 | F32: 8 | G32: Panasonic | H32: Digikey | I32: ECQ-E2223J
D33: Capacitor 0.047uF | E33: C71B | F33: 1 | G33: Panasonic | H33: Digikey | I33: ECQ-E2473J
B34: 41 | D34: Capacitor 0.1uF | E34: C4, C8, C11, C14, C20, C24, C27, C30, C73, C74, C77 | F34: 11 | G34: Panasonic | H34: Digikey | I34: ECQ-E2104J
D35: Capacitor 0.33uF | E35: C71A | F35: 1 | G35: Panasonic | H35: Digikey | I35: ECQ-E2333J
B36: 45 | D36: Capacitor 10uF | E36: C79, C82 | F36: 2 | G36: Panasonic | H36: Digikey | I36: ECE-A1EKA100I
B37: 47 | D37: Capacitor 47uF | E37: C81, C83 | F37: 2 | G37: Panasonic | H37: Digikey | I37: ECA-1EM470I
B38: 51 | D38: Diode DO-34 | E38: D2, D3 | F38: 2 | G38: Farichild | H38: Digikey | I38: 1N4148
B39: 48 | D39: Header, 20X2 | E39: CN7B | F39: 1 | G39: Molex | H39: Digikey | I39: 63453-140LF
B40: 53 | D40: Op Amp, Quad JFET | E40: IC1, IC3, IC5, IC7 | F40: 4 | G40: TI | H40: Digikey | I40: LF347N
B41: 55 | D41: Op Amp, Quad JFET | E41: IC9, IC10, IC11, IC42, IC43 | F41: 5 | G41: TI | H41: Digikey | I41: TL084CN
B42: 54 | D42: OTA, Dual | E42: IC2, IC4, IC6, IC8, IC12, IC13, IC14, IC15 | F42: 9 | G42: Col Audio | H42: Digikey | I42: V13700
B43: 56 | D43: Logic Latch | E43: IC16, IC19, IC22, IC25, IC28, IC31, IC34, IC37, IC40 | F43: 9 | G43: TI | H43: Digikey | I43: SN74HC174N
B44: 57 | D44: Analog Switch | E44: IC17, IC18, IC20, IC21, IC23, IC24, IC26, IC27, IC29, IC30, IC32, IC33, IC35, IC36 | F44: 14 | G44: Vishay | H44: Digikey | I44: DG409DJ-E3
B45: 58 | D45: Analog Switch | E45: IC38, IC39 | F45: 2 | G45: Vishay | H45: Digikey | I45: DG408DJ-E3
B46: 59 | D46: Analog Switch | E46: IC41 | F46: 1 | G46: TI | H46: Digikey | I46: SN74LV4051AN
A47: 1 | B47: 66 | D47: Op Amp, Dual JFET | E47: IC100 | F47: 16 | G47: TI | H47: Digikey | I47: TL072CP
B48: 68 | D48: Transistor, BJT, PNP | E48: Q1, Q3, Q5, Q6, Q7, Q8, Q9, Q10, Q11, Q12, Q13, Q14, Q15, Q16, Q18, Q21 | F48: 16 | G48: On Semi | H48: Digikey | I48: BC557B
B49: 69 | D49: Transistor, BJT, NPN | E49: Q2, Q4, Q19, Q20, Q22, Q23, Q24 | F49: 7 | G49: On Semi | H49: Digikey | I49: BC547B
B50: 70 | D50: Transistor, NJFET | E50: Q17, Q20 | F50: 2 | G50: On Semi | H50: Digikey | I50: J112
B51: 71 | D51: Trimmer 10k | E51: TM1, TM2 | F51: 2 | G51: Bourns | H51: Digikey | I51: 3362P-1-103LF
B52: 72 | D52: Trimmer 100k | E52: TM3, TM4 | F52: 2 | G52: Bourns | H52: Digikey | I52: 3362P-1-104LF
...

Sheet OB-R Voice Mobo
B2: ITEM | C2: DESCRIPTION | D2: DESIGNATOR | E2: QTY | F2: MANUFACTURER | G2: VENDOR | H2: PART NUMBER | I2: DIY PRICE | J2: DIY EXT | K2: PRICE | L2: EXT
B3: 1 | C3: Resistor 100 5% CF | D3: R14, R31, R48, R65 | E3: 4 | F3: Stackpole | G3: DIGIKEY | H3: CF14JT100R | I3: 0.02 | J3: =I3*E3 -> 0.08 | K3: 0.00729 | L3: =K3*E3 -> 0.02916
B4: 2 | C4: Resistor 499 1% MF | D4: R2, R4, R6, R8, R19, R21, R23, R25, R36, R38, R40, R42, R53, R55, R57, R59, R78, R80, R82, R84 | E4: 20 | F4: Yageo | G4: DIGIKEY | H4: MFR-25FBF52-499R | I4: 0.02 | J4: =I4*E4 -> 0.4 | K4: 0.0300 | L4: =K4*E4 -> 0.6
B5: 3 | C5: Resistor 10k 5% CF | D5: R9, R15, R17, R26, R32, R34, R43, R49, R51, R60, R66, R68 | E5: 12 | F5: Stackpole | G5: DIGIKEY | H5: CF14JT10K0 | I5: 0.02 | J5: =I5*E5 -> 0.24 | K5: 0.00729 | L5: =K5*E5 -> 0.08748
B6: 4 | C6: Resistor 22k 5% CF | D6: R16, R33, R50, R67 | E6: 4 | F6: Stackpole | G6: DIGIKEY | H6: CF14JT22K0 | I6: 0.02 | J6: =I6*E6 -> 0.08 | K6: 0.00729 | L6: =K6*E6 -> 0.02916
B7: 5 | C7: Resistor 23.7k 1% MF | D7: R10, R11, R12, R27, R28, R29, R44, R45, R46, R61, R62, R63 | E7: 12 | F7: Stackpole | G7: DIGIKEY | H7: CMF5023K700FHEB | I7: 0.02 | J7: =I7*E7 -> 0.24 | K7: $0.46 | L7: =K7*E7 -> 5.52
B8: 6 | C8: Resistor 30k 5% CF | D8: R1, R3, R5, R7, R18, R20, R22, R24, R35, R37, R39, R41, R52, R54, R56, R58, R77, R79, R81, R83, R85, R86, R88, R89 | E8: 24 | F8: Stackpole | G8: DIGIKEY | H8: CF14JT30K0 | I8: 0.02 | J8: =I8*E8 -> 0.48 | K8: 0.00729 | L8: =K8*E8 -> 0.17496
B9: 7 | C9: Resistor 47k 5% CF | D9: R69, R70, R71, R72, R73, R74, R75, R76 | E9: 8 | F9: Stackpole | G9: DIGIKEY | H9: CF14JT47K0 | I9: 0.02 | J9: =I9*E9 -> 0.16 | K9: 0.00729 | L9: =K9*E9 -> 0.05832
B10: 8 | C10: Resistor 100k 5% CF | D10: R13, R30, R47, R64, R87 | E10: 5 | F10: Xicon | G10: MOUSER | H10: 270-100K-RC | I10: 0.02 | J10: =I10*E10 -> 0.1 | K10: 0.00729 | L10: =K10*E10 -> 0.03645
B11: 9 | C11: Capacitor 100pF 5% X7R | D11: C13, C19, C25, C31, C49, C50 | E11: 6 | F11: Vishay | G11: DIGIKEY | H11: K101J15C0GF53L2 | I11: 0.12 | J11: =I11*E11 -> 0.72 | K11: 0.04 | L11: =K11*E11 -> 0.24
B12: 10 | C12: Capacitor 560pF C0G | D12: C9, C10, C11, C12, C15, C16, C17, C18, C21, C22, C23, C24, C27, C28, C29, C30 | E12: 36 | F12: Vishay | G12: DIGIKEY | H12: K560J15C0GF5TH5 | I12: 0.12 | J12: =I12*E12 -> 4.32 | K12: 0.068 | L12: =K12*E12 -> 2.448
B13: 11 | C13: Capacitor 0.1uF 10% X7R | D13: C33, C34, C35, C36, C37, C38, C39, C40, C41, C42, C43, C44, C55, C56, C57, C58 | E13: 16 | F13: Vishay | G13: DIGIKEY | H13: K104K15X7RF53H5 | I13: 0.12 | J13: =I13*E13 -> 1.92 | K13: 0.033 | L13: =K13*E13 -> 0.528
B14: 12 | C14: Capacitor 0.47uF PF | D14: C51, C52, C53, C54 | E14: 4 | F14: Panasonic | G14: DIGIKEY | H14: ECQ-E2474JB3 | I14: 0.4 | J14: =I14*E14 -> 1.6 | K14: 0.21 | L14: =K14*E14 -> 0.84
B15: 13 | C15: Capacitor 6.8uF Elec | D15: C14, C20, C26, C32 | E15: 4 | F15: Panasonic | G15: DIGIKEY | H15: EEA-FC1V6R8H | I15: 0.15 | J15: =I15*E15 -> 0.6 | K15: $0.10 | L15: =K15*E15 -> 0.4
B16: 14 | C16: Diode, Schottky SOT323 | D16: D10, D11 | E16: 2 | F16: NXP | G16: DIGIKEY | H16: BAT85 | I16: 0.1 | J16: =I16*E16 -> 0.2 | K16: $0.15 | L16: =K16*E16 -> 0.3
B17: 15 | C17: Op Amp, Dual JFETTL072 | D17: IC5, IC8, IC11, IC14, IC19 | E17: 5 | F17: TI | G17: DIGIKEY | H17: TL072CD | I17: 0.68 | J17: =I17*E17 -> 3.4 | K17: $0.17 | L17: =K17*E17 -> 0.85
B18: 16 | C18: Op Amp, Single JFET | D18: IC17 | E18: 1 | F18: TI | G18: DIGIKEY | H18: TL081CP | I18: 0 | J18: =I18*E18 -> 0 | K18: $0.15 | L18: =K18*E18 -> 0.15
B19: 17 | C19: IC, Diode Array | D19: IC6, IC9, IC12, IC15 | E19: 4 | F19: Intersil | G19: ABSTRAKT | H19: CA3019 | I19: 0 | J19: =I19*E19 -> 0 | K19: $10.00 | L19: =K19*E19 -> 40
B20: 18 | C20: IC, OTA | D20: IC7, IC10, IC13, IC16 | E20: 4 | F20: Rochester | G20: ROCHESTER | H20: CA3080AE | I20: 0 | J20: =I20*E20 -> 0 | K20: $3.25 | L20: =K20*E20 -> 13
B21: 19 | C21: IC, VCA | D21: IC1, IC2, IC3, IC4, IC18 | E21: 5 | F21: Cool Audio | G21: COOL AUDIO | H21: V2164 | I21: 3.6 | J21: =I21*E21 -> 18 | K21: $1.60 | L21: =K21*E21 -> 8
B22: 20 | C22: Connector, Phone Jack, Mono | D22: J1, J2, J3, J4, J5, J6, J8, J9, J10, J11, J12, J13, J14 | E22: 13 | F22: Amphenol | G22: DIGIKEY | H22: ACJM-MHDR | I22: 1.11 | J22: =I22*E22 -> 14.43 | K22: $0.69 | L22: =K22*E22 -> 8.97
B23: 21 | C23: Connector, Phone Jack, Stereo | D23: J5, J6 | E23: 2 | F23: Amphenol | G23: ONLINECOMP | H23: ACJS-MHDR | I23: 1.36 | J23: =I23*E23 -> 2.72 | K23: $0.95 | L23: =K23*E23 -> 1.9
B24: 22 | C24: Trimpot 100k | D24: TM1, TM2, TM3, TM4 | E24: 4 | F24: Bourns | G24: ONLINECOMP | H24: 3362P-1-104LF | I24: 0.75 | J24: =I24*E24 -> 3 | K24: $0.429 | L24: =K24*E24 -> 1.716
B25: 23 | C25: Header, 2x15 2mm LS | D25: CN1, CN2, CN3, CN4 | E25: 4 | F25: Generic | G25: NEW DEPARTURE | H25: Generic | I25: 0 | J25: =I25*E25 -> 0 | K25: $0.40 | L25: =K25*E25 -> 1.6
B26: 24 | C26: Header, 3POS, 3.96mm LS | D26: A1, A2, A3, A4, A5, A6, A7, A8, C1, C2, C3, C4, C5, C6, C7, C8 | E26: 16 | F26: Molex | G26: ONLINECOMP | H26: 26-60-2030 | I26: 0.43 | J26: =I26*E26 -> 6.88 | K26: $0.212 | L26: =K26*E26 -> 3.392
... B32: 30 | C32: Header, 10POS, 3.96mm LS | D32: D1, D2, D3, D4, D5, D6, D7, D8, E1, E2, E3, E4, E5, E6, E7, E8 | E32: 16 | F32: Molex | G32: ONLINECOMP | H32: 26-60-2100 | I32: 1.56 | J32: =I32*E32 -> 24.96 | K32: $0.76 | L32: =K32*E32 -> 12.16
B33: 31 | C33: PCB, OB-R Voice Mobo | E33: 1 | F33: Gold Phoenix | G33: GOLD PHOENIX | H33: PCB, OB-R Voice Mobo | I33: 0 | J33: =I33*E33 -> 0 | K33: 16.68 | L33: =K33*E33 -> 16.68
B34: 32 | C34: Assembly, OB-R Voice Mobo | E34: 1 | F34: Gold Phoenix | G34: GOLD PHOENIX | H34: Assembly, OB-R Voice Mobo | I34: 0 | J34: =I34*E34 -> 0 | K34: 10 | L34: =K34*E34 -> 10
J35: =SUM(J3:J34) -> 97.552 | L35: =SUM(L3:L34) -> 137.48553
G36: VOICE CARDS | L36: =K33 -> 16.68
F37: 95 | G37: 8-Voice | H37: 760
F38: 42 | G38: 4-Voice | H38: 168
F39: 30 | G39: 2-Voice | H39: 60
F40: =SUM(F37:F39) -> 167 | H40: =SUM(H37:H39) -> 988
F41: 220 sets | G41: Board sets Required

Sheet OB-R Voice Card RevA
B2: ITEM | C2: DESCRIPTION | D2: DESIGNATOR | E2: QTY/CARD | F2: QTY (8) CARDS | G2: VENDOR | H2: MANUFACTURER | I2: PART NUMBER | J2: DIY PRICE | K2: DIY EXT | L2: PRICE | M2: EXT
B3: 1 | C3: Resistor 0 | D3: R103 | E3: 1 | F3: 8 | G3: DIGIKEY | H3: Stackpole | I3: CF14JT00 | J3: 0.02 | K3: =J3*F3 -> 0.16 | L3: 0.0079 | M3: =L3*E3 -> 0.0079
B4: 2 | C4: Resistor 10 | D4: R100, R101, R102, R104, R105, R106 | E4: 6 | F4: 48 | G4: DIGIKEY | H4: Stackpole | I4: CF14JT10R0 | J4: 0.02 | K4: =J4*F4 -> 0.96 | L4: 0.0079 | M4: =L4*E4 -> 0.0474
B5: 3 | C5: Resistor 24 | D5: R110, R111 | E5: 2 | F5: 16 | G5: DIGIKEY | H5: Stackpole | I5: CF14JT24R0 | J5: 0.02 | K5: =J5*F5 -> 0.32 | L5: 0.0079 | M5: =L5*E5 -> 0.0158
B6: 4 | C6: Resistor 220 | D6: R88, R91, R98, R115 | E6: 4 | F6: 32 | G6: DIGIKEY | H6: Stackpole | I6: CF14JT220R | J6: 0.02 | K6: =J6*F6 -> 0.64 | L6: 0.0079 | M6: =L6*E6 -> 0.0316
B7: 5 | C7: Resistor 470 | D7: R30, R68 | E7: 2 | F7: 16 | G7: DIGIKEY | H7: Stackpole | I7: CF14JT470R | J7: 0.02 | K7: =J7*F7 -> 0.32 | L7: 0.0079 | M7: =L7*E7 -> 0.0158
B8: 6 | C8: Resistor 680 | D8: R108, R109 | E8: 2 | F8: 16 | G8: DIGIKEY | H8: Stackpole | I8: CF14JT680R | J8: 0.02 | K8: =J8*F8 -> 0.32 | L8: 0.0079 | M8: =L8*E8 -> 0.0158
B9: 7 | C9: Resistor 1k | D9: R31, R32, R69, R117, R119, R128, R138 | E9: 7 | F9: 56 | G9: DIGIKEY | H9: Stackpole | I9: CF14JT1K00 | J9: 0.02 | K9: =J9*F9 -> 1.12 | L9: 0.0079 | M9: =L9*E9 -> 0.0553
B10: 8 | C10: Resistor PTC 1k | D10: R13, R51 | E10: 2 | F10: 16 | G10: KRL-BANTRY | H10: KRL | I10: 1KQ | J10: 2.85 | K10: =J10*F10 -> 45.6 | L10: 1.99 | M10: =L10*E10 -> 3.98
B11: 9 | C11: Resistor 1.5k | D11: R22, R23, R60, R61 | E11: 4 | F11: 32 | G11: DIGIKEY | H11: Stackpole | I11: CF14JT1K50 | J11: 0.02 | K11: =J11*F11 -> 0.64 | L11: 0.0079 | M11: =L11*E11 -> 0.0316
B12: 10 | C12: Resistor 2.2k | D12: R19, R57, R71, R131 | E12: 4 | F12: 32 | G12: DIGIKEY | H12: Stackpole | I12: CF14JT2K20 | J12: 0.02 | K12: =J12*F12 -> 0.64 | L12: 0.0079 | M12: =L12*E12 -> 0.0316
B13: 11 | C13: Resistor 2.7k | D13: R24, R62 | E13: 2 | F13: 16 | G13: DIGIKEY | H13: Stackpole | I13: CF14JT2K70 | J13: 0.02 | K13: =J13*F13 -> 0.32 | L13: 0.0079 | M13: =L13*E13 -> 0.0158
B14: 12 | C14: Resistor 3.3k | D14: R42, R78 | E14: 2 | F14: 16 | G14: DIGIKEY | H14: Stackpole | I14: CF14JT3K30 | J14: 0.02 | K14: =J14*F14 -> 0.32 | L14: 0.0079 | M14: =L14*E14 -> 0.0158
... B55: 53 | C55: Analog Switch | D55: A7 | E55: 1 | F55: 8 | G55: DIGIKEY | H55: TI | I55: CD4053BE | J55: 0.38 | K55: =J55*F55 -> 3.04 | L55: 0.52 | M55: =L55*E55 -> 0.52
C56: Analog Switch | D56: Rear | E56: 1 | F56: 8 | G56: DIGIKEY | H56: Vishay | I56: DG409DQ-T1-E3 | J56: 1.75 | K56: =J56*F56 -> 14 | L56: 1.15 | M56: =L56*E56 -> 1.15
B57: 54 | C57: Op Amp, Single JEFT | D57: A1, A2, A4, A5 | E57: 4 | F57: 32 | G57: DIGIKEY | H57: TI | I57: uA741CP | J57: 0.32 | K57: =J57*F57 -> 10.24 | L57: 0.58 | M57: =L57*E57 -> 2.32
B58: 55 | C58: Op Amp, Single JEFT | D58: A6, A8, A9, A16, A17 | E58: 5 | F58: 40 | G58: DIGIKEY | H58: ST | I58: TL081CP | J58: 0.32 | K58: =J58*F58 -> 12.8 | L58: 0.45 | M58: =L58*E58 -> 2.25
B59: 56 | C59: Op Amp, Dual JEFT | D59: A11 | E59: 1 | F59: 8 | G59: DIGIKEY | H59: ST | I59: TL082CP | J59: 0.55 | K59: =J59*F59 -> 4.4 | L59: 0.81 | M59: =L59*E59 -> 0.81
B60: 57 | C60: ADSR IC | D60: A18, A19 | E60: 2 | F60: 16 | G60: ALFA RPAR | H60: Alfa Rpar | I60: AS3310-DIL | J60: 6.5 | K60: =J60*F60 -> 104 | L60: 1.99 | M60: =L60*E60 -> 3.98
B61: 58 | C61: OTA, Single | D61: A10, A12, A13, A14, A15 | E61: 5 | F61: 40 | G61: ROCHESTER | H61: Rochester | I61: CA3080AE | J61: 4.25 | K61: =J61*F61 -> 170 | L61: 4.25 | M61: =L61*E61 -> 21.25
B62: 59 | C62: Transistor Array | D62: A3 | E62: 1 | F62: 8 | G62: ROCHESTER | H62: Rochester | I62: LM3086J | J62: 1.5 | K62: =J62*F62 -> 12 | L62: 0.99 | M62: =L62*E62 -> 0.99
B63: 60 | C63: Voltage Regulator | D63: A21 | E63: 1 | F63: 8 | G63: DIGIKEY | H63: ST | I63: 7815CV | J63: 0.75 | K63: =J63*F63 -> 6 | L63: 0.5 | M63: =L63*E63 -> 0.5
B64: 61 | C64: Voltage Regulator | D64: A20 | E64: 1 | F64: 8 | G64: DIGIKEY | H64: ST | I64: 7915CV | J64: 0.75 | K64: =J64*F64 -> 6 | L64: 0.6 | M64: =L64*E64 -> 0.6
B65: 62 | C65: PNP BJT | D65: Q5, Q6, Q9, Q14, Q15, Q20, Q21, Q22, Q24 | E65: 9 | F65: 72 | G65: DIGIKEY | H65: Central Semi | I65: 2N3905 | J65: 0.75 | K65: =J65*F65 -> 54 | L65: 0.5 | M65: =L65*E65 -> 4.5
B66: 63 | C66: NPN BJT | D66: Q1, Q2, Q7, Q8, Q10, Q11, Q16, Q17, Q18, Q19, Q23, Q25 | E66: 12 | F66: 96 | G66: ABSTRAKT | H66: Misc | I66: MPS5172 | J66: 0.5 | K66: =J66*F66 -> 48 | L66: 0.25 | M66: =L66*E66 -> 3
B67: 64 | C67: JFET | D67: Q3, Q4, Q12, Q13 | E67: 4 | F67: 32 | G67: DIGIKEY | H67: Fairchild | I67: J112 | J67: 0.54 | K67: =J67*F67 -> 17.28 | L67: 0.54 | M67: =L67*E67 -> 2.16
B68: 65 | C68: LED, Red | D68: D6 | E68: 1 | F68: 8 | G68: DIGIKEY | H68: Kingbright | I68: WP7113ID | J68: 0.15 | K68: =J68*F68 -> 1.2 | L68: 0.083 | M68: =L68*E68 -> 0.083
... B79: 76 | C79: Header, 4-Pin | D79: F | E79: 1 | F79: 8 | G79: DIGIKEY | H79: Molex | I79: 09-48-4049 | J79: 0.95 | K79: =J79*F79 -> 7.6 | L79: 1.13 | M79: =L79*E79 -> 1.13
B80: 77 | C80: Header, 8-Pin | D80: B | E80: 1 | F80: 8 | G80: DIGIKEY | H80: Molex | I80: 09-48-4089 | J80: 1.93 | K80: =J80*F80 -> 15.44 | L80: 2.7 | M80: 2.7
B81: 78 | C81: PCB, OB-R Voice Card | E81: 1 | F81: 8 | G81: GOLD PHOENIX | H81: Gold Phoenix | I81: PCB, OB-R Voice Card | J81: 0 | K81: =J81*F81 -> 0 | L81: 3.89 | M81: =L81*E81 -> 3.89
B82: 79 | C82: Assembly, OB-R Voice Card | E82: 1 | F82: 8 | G82: GOLD PHOENIX | H82: Gold Phoenix | I82: Assembly, OB-R Voice Card | J82: 0 | K82: =J82*F82 -> 0 | L82: 4.5 | M82: =L82*E82 -> 4.5
K83: =SUM(K3:K82) -> 923.52 | M83: =SUM(M3:M74) -> 73.3697
M84: =L81+M56 -> 5.04

Sheet OB-R DAC Board
B2: ITEM | C2: DESCRIPTION | D2: DESIGNATOR | E2: VENDOR | F2: MANUFACTURER | G2: PART NUMBER | H2: QTY | I2: PRICE | J2: EXT
B3: 1 | C3: Resistor 4.87k 0603 | D3: R23, R25, R26, R28, R31, R33, R34, R36, R39, R41, R42, R44 | E3: MOUSER | F3: Yageo | G3: RC0603FR-TBD | H3: 12 | I3: $0.004 | J3: =I3*H3 -> 0.048
B4: 2 | C4: Resistor 10k 0603 | D4: R1, R2, R3, R4, R5 | E4: MOUSER | F4: Yageo | G4: RC0603FR-0710KL | H4: 5 | I4: $0.004 | J4: =I4*H4 -> 0.02
B5: 3 | C5: Resistor 47k 0603 | D5: R6, R7, R8, R9, R10, R11, R12, R13, R14, R15, R16, R17, R18, R19, R20, R21 | E5: MOUSER | F5: Yageo | G5: RC0603FR-1047KL | H5: 16 | I5: $0.004 | J5: =I5*H5 -> 0.064
B6: 4 | C6: Resistor 100k 0603 | D6: R22, R24, R27, R29, R30, R32, R35, R37, R38, R40, R43, R45 | E6: MOUSER | F6: Yageo | G6: RC0603FR-1047KL | H6: 12 | I6: $0.004 | J6: =I6*H6 -> 0.048
B7: 5 | C7: Capacitor 1uF | D7: C1, C2 | E7: MOUSER | F7: Yageo | G7: CC0603KRX5R8BB105 | H7: 2 | I7: $0.02 | J7: =I7*H7 -> 0.04
B8: 6 | C8: Capacitor 0.1uF MLCC 0603 | D8: C3, C4 | E8: MOUSER | F8: TBD | G8: TBD | H8: 2 | I8: $0.06 | J8: =I8*H8 -> 0.12
B9: 7 | C9: Capacitor 0.01uF MLCC 0603 | D9: C5, C6, C7, C8, C9, C10, C11, C12, C13, C14, C15, C16, C17, C18, C19, C20, C21, C22, C23, C24, C25, C26, C27, C28, C29, C30, C31, C32, C33, C34, C35, C37, C38, C38, C39, C40, C41, C42, C43, C44, C45, C46, C47, C48, C49, C50, C51, C52, C53, C54, C55, C60, C61, C62, C67, C68, C73, C74, C75, C80, C81, C82, C83, C84, C85, C86, C87, C88, C89, C90, C91, C92, C93, C94, C95, C96, C97, C98, C99, C100, C101, C102, C103, C104, C105, C106, C107, C112, C113, C114, C119, C120, C125, C126, C127, C132 | E9: MOUSER | F9: Murata | G9: GRM1885C1E103JA01D | H9: 96 | I9: $0.02 | J9: =I9*H9 -> 1.92
B10: 8 | C10: Capacitor 1nF MLCC 0603 | D10: C56, C57, C58, C59, C63, C64, C65, C66, C69, C70, C71, C72, C76, C77, C78, C79, C108, C109, C110, C111, C115, C116, C117, C118, C121, C122, C123, C124, C128, C129, C130, C131 | E10: MOUSER | F10: Murata | G10: GRM1885C1H102JA01D | H10: 32 | I10: $0.033 | J10: =I10*H10 -> 1.056
B11: 11 | C11: Vref | D11: IC1 | E11: MOUSER | F11: TI | G11: REF3030AID | H11: 1 | I11: $0.90 | J11: =I11*H11 -> 0.9
B12: 12 | C12: DAC, 16-bit | D12: IC2 | E12: AD | F12: AD | G12: AD5676R | H12: 1 | I12: $8.90 | J12: =I12*H12 -> 8.9
B13: 13 | C13: Op Amp, Quad JFET | D13: IC3, IC4 | E13: MOUSER | F13: TI | G13: LF347D | H13: 2 | I13: $0.42 | J13: =I13*H13 -> 0.84
B14: 14 | C14: Analog Switch | D14: IC5, IC8, IC11, IC14, IC20, IC23, IC26, IC29, IC32, IC35 | E14: MOUSER | F14: TI | G14: CD4051BM96 | H14: 10 | I14: $0.165 | J14: =I14*H14 -> 1.65
... B16: 16 | C16: Op Amp, Quad JFET | D16: IC15, IC16, IC17, IC18, IC19, IC21, IC22 | E16: MOUSER | F16: TI | G16: TL084CDR | H16: 7 | I16: $0.18 | J16: =I16*H16 -> 1.26
B17: 10 | C17: Header, 12POS, Female | D17: DAC, IO4 | E17: MOUSER | F17: Molex | G17: 79109-1005 | H17: 2 | I17: 1.48 | J17: =I17*H17 -> 2.96
B18: 17 | C18: Header, 30POS, Female | D18: IO1, IO2, IO3 | E18: MOUSER | F18: Molex | G18: 87831-3010 | H18: 3 | I18: 1.37 | J18: =I18*H18 -> 4.11
B19: 9 | C19: Header, 30POS, Male | D19: CN1, CN2, CN3, CN4 | E19: NEWDEPARTURE | F19: Generic | G19: Generic | H19: 4 | I19: 0.21 | J19: =I19*H19 -> 0.84
B20: 18 | C20: PCB, OB-R DAC Board | D20: NA | E20: GOLD PHOENIX | F20: Gold Phoenix | G20: PCB, OB-R DAC Board | H20: 1 | I20: 4.8 | J20: =I20*H20 -> 4.8
B21: 19 | C21: Assembly, OB-R DAC Board | D21: NA | E21: GOLD PHOENIX | F21: Gold Phoenix | G21: Assembly, OB-R DAC Board | H21: 1 | I21: 7 | J21: =I21*H21 -> 7
J22: =SUM(J3:J21) -> 38.536
B30: SH-101 | C30: 1350
B31: OB-R 8-Voice | C31: 1900

Sheet OB-R Panel
B2: ITEM | C2: DESCRIPTION | D2: DESIGNATOR | E2: QTY | F2: VENDOR | G2: MANUFACTURER | H2: PART NUMBER | I2: DIY PRICE | J2: DIY EXT | K2: PRICE | L2: EXT
B3: 1 | C3: Resistor 10k | D3: R169, R170, R171, R172 | E3: 4 | F3: DIGIKEY | G3: Generic | H3: 270-10k-RC | I3: 0.02 | J3: =I3*E3 -> 0.08 | K3: $0.01 | L3: =K3*E3 -> 0.04
B4: 2 | C4: Capacitor 10nF | D4: C43, C44 | E4: 2 | F4: DIGIKEY | G4: Murata | H4: FA28C0G2A103JRU6 | I4: 0.43 | J4: =I4*E4 -> 0.86 | K4: $0.02 | L4: =K4*E4 -> 0.04
B5: 3 | C5: Capacitor 0.1uF | D5: C1, C2, C3, C4, C5, C6, C7, C8, C9, C10, C11, C12, C13, C14, C15, C16, C17, C18, C19, C20, C21, C22, C23, C24, C25, C26, C27, C28, C29, C30, C31, C32, C33, C34, C35, C36, C37, C38, C39, C40, C41, C42 | E5: 42 | F5: DIGIKEY | G5: AVX | H5: FA16C0G2A473JRU06 | I5: 0.5 | J5: =I5*E5 -> 21 | K5: $0.10 | L5: =K5*E5 -> 4.2
B6: 4 | C6: Diode | D6: D1, D2, D3, D4, D5, D6, D7, D8, D9, D10, D11, D12, D13, D14, D15, D16, D17, D18, D19, D20, D21, D22, D23, D24, D25, D26, D27, D28, D29, D30, D31, D32, D33, D34, D35, D36, D37, D38, D39, D40 | E6: 30 | F6: DIGIKEY | G6: Fairchild | H6: 1N4148 | I6: 0.01 | J6: =I6*E6 -> 0.3 | K6: $0.00 | L6: =K6*E6 -> 0
B7: 5 | C7: Encoder | D7: E1 | E7: 1 | F7: DIGIKEY | G7: Bourns | H7: PEC12R-4025F-S0024 | I7: 1.1 | J7: =I7*E7 -> 1.1 | K7: 0.86 | L7: =K7*E7 -> 0.86
B8: 6 | C8: Analog Switch | D8: IC1, IC2, IC3, IC4, IC5, IC6 | E8: 6 | F8: DIGIKEY | G8: TI | H8: SN74LV4051AN | I8: 0.8 | J8: =I8*E8 -> 4.8 | K8: 0.34 | L8: =K8*E8 -> 2.04
B9: 7 | C9: LED | D9: LED34, LED35, LED36, LED37, LED38, LED39, LED40, LED41, LED42, LED43, LED44, LED45, LED46, LED47, LED48 | E9: 12 | F9: DIGIKEY | G9: Kingbright | H9: WP710A10HD | I9: 0.16 | J9: =I9*E9 -> 1.92 | K9: $0.04 | L9: =K9*E9 -> 0.48
B10: 8 | C10: Potentiometer, Endless | D10: P1, P2, P3, P4, P5, P6, P7, P8, P9, P10, P11, P12, P13, P14, P15, P16, P17, P18, P19, P20, P21 | E10: 21 | F10: DIGIKEY | G10: Alpha | H10: RV14-series | I10: 0 | J10: =I10*E10 -> 0 | K10: $0.70 | L10: =K10*E10 -> 14.7
B11: 9 | C11: Push Switch | D11: SW3, SW5, SW14, SW15 | E11: 4 | F11: TBD | G11: HongJu | H11: PB86-A0 | I11: 0.93 | J11: =I11*E11 -> 3.72 | K11: 0.6 | L11: =K11*E11 -> 2.4
B12: 10 | C12: Push Switch w/ Led | D12: S11, SW1, SW2, SW7, SW8, SW16, SW17, SW18, SW19, SW20, SW21, SW22, SW23, SW24, SW25, SW26, SW27, SW28, SW29, SW30, SW31 | E12: 21 | F12: TBD | G12: HongJu | H12: PB86-A1 | I12: 0.93 | J12: =I12*E12 -> 19.53 | K12: 0.6 | L12: =K12*E12 -> 12.6
B13: 11 | C13: Push Switch Dual LED | D13: SW4, SW6, SW9, SW10, SW12, SW13 | E13: 6 | F13: TBD | G13: HongJu | H13: PB86-A2 | I13: 0.93 | J13: =I13*E13 -> 5.58 | K13: 0.6 | L13: =K13*E13 -> 3.6
B14: 12 | C14: SW DIP-8 | D14: VOICES | E14: 1 | F14: DIGIKEY | G14: C&K | H14: BPA08B | I14: 1.95 | J14: =I14*E14 -> 1.95 | K14: 1.64 | L14: =K14*E14 -> 1.64
B15: 13 | C15: Header 20X2 | D15: CN7B | E15: 1 | F15: DIGIKEY | G15: TBD | H15: 87831-4010 | I15: 3.153 | J15: =I15*E15 -> 3.153 | K15: 1 | L15: =K15*E15 -> 1
B16: 14 | C16: OLED, 128x64 | D16: OLED | E16: 1 | F16: GENERIC | G16: GENERIC | H16: GENERIC | I16: 10 | J16: =I16*E16 -> 10 | K16: 6.5 | L16: =K16*E16 -> 6.5
B17: 15 | C17: PCB, OB-R Panelboard | D17: NA | E17: 1 | F17: GOLD PHOENIX | G17: Gold Phoenix | H17: PCB, OB-R Panelboard | I17: 0 | J17: =I17*E17 -> 0 | K17: 7 | L17: =K17*E17 -> 7
B18: 16 | C18: Assembly, OB-R Panelboard | D18: NA | E18: 1 | F18: GOLD PHOENIX | G18: Gold Phoenix | H18: Assembly, OB-R Panelboard | I18: 0 | J18: =I18*E18 -> 0 | K18: 7 | L18: =K18*E18 -> 7
J19: =SUM(J3:J18) -> 73.993 | L19: =SUM(L3:L18) -> 64.1
L20: =K17+L10 -> 21.7

Sheet Power Supply
B2: ITEM | C2: DESCRIPTION | D2: DESIGNATOR | E2: QTY | F2: VENDOR | G2: MANUFACTURER | H2: PART NUMBER | I2: DIY PRICE | J2: DIY EXT | K2: PRICE | L2: EXT
B3: 1 | C3: SMPSU | D3: NA | E3: 1 | F3: MOUSER | G3: MEAN WELL | H3: RT-125C | I3: 34.1 | J3: =I3*E3 -> 34.1 | K3: 29.31 | L3: =K3*E3 -> 29.31
B4: 2 | C4: Resistor 120 Ohms | D4: R1, R3 | E4: 2 | F4: MOUSER | G4: XICON | H4: 270-120-RC | I4: 0.02 | J4: =I4*E4 -> 0.04 | K4: 0.01 | L4: =K4*E4 -> 0.02
B5: 3 | C5: resistor 1k Ohms | D5: R5 | E5: 1 | F5: MOUSER | G5: XICON | H5: 270-1k-RC | I5: 0.02 | J5: =I5*E5 -> 0.02 | K5: 0 | L5: =K5*E5 -> 0
B6: 4 | C6: Resistor 1.24k Ohms | D6: R2, R4 | E6: 2 | F6: MOUSER | G6: XICON | H6: 270-1.24k-RC | I6: 0.02 | J6: =I6*E6 -> 0.04 | K6: 0.01 | L6: =K6*E6 -> 0.02
B7: 5 | C7: Capacitor 0.1uF | D7: C1, C2, C3, C4, C5, C6 | E7: 6 | F7: MOUSER | G7: TDK | H7: FA16C0G2A473JRU06 | I7: 0.5 | J7: =I7*E7 -> 3 | K7: $0.10 | L7: =K7*E7 -> 0.6
B8: 6 | C8: Capacitor 10uF | D8: C7, C8, C9, C10 | E8: 4 | F8: MOUSER | G8: PANASONIC | H8: EEU-FC1H100L | I8: 0.29 | J8: =I8*E8 -> 1.16 | K8: 0.08 | L8: =K8*E8 -> 0.32
B9: 7 | C9: Capacitor 100uF | D9: C11, C12, C13, C14, C15, C16, C17, C18 | E9: 8 | F9: MOUSER | G9: PANASONIC | H9: EEU-FC1V470 | I9: 0.21 | J9: =I9*E9 -> 1.68 | K9: 0.12 | L9: =K9*E9 -> 0.96
B10: 8 | C10: Diode | D10: D1 | E10: 1 | F10: MOUSER | G10: FAIRCHILD | H10: 1N4148 | I10: 0.02 | J10: =I10*E10 -> 0.02 | K10: 0 | L10: =K10*E10 -> 0
B11: 9 | C11: VREG | D11: IC1 | E11: 1 | F11: MOUSER | G11: ST | H11: LM2941T/NOPB | I11: 1.58 | J11: =I11*E11 -> 1.58 | K11: 1.34 | L11: =K11*E11 -> 1.34
B12: 10 | C12: VREG | D12: IC2 | E12: 1 | F12: MOUSER | G12: ST | H12: LM2991T/NOPB | I12: 3.39 | J12: =I12*E12 -> 3.39 | K12: 2 | L12: =K12*E12 -> 2
B13: 11 | C13: VREG | D13: IC3 | E13: 1 | F13: MOUSER | G13: ST | H13: LM1086CT-3.3/NOPB | I13: 1.85 | J13: =I13*E13 -> 1.85 | K13: 1.58 | L13: =K13*E13 -> 1.58
B14: 12 | C14: VSUP | D14: IC4 | E14: 1 | F14: MOUSER | G14: Maxim | H14: DS1818-10 | I14: 2.26 | J14: =I14*E14 -> 2.26 | K14: 1.63 | L14: =K14*E14 -> 1.63
B15: 13 | C15: TRIMMER | D15: TM1, TM2 | E15: 2 | F15: MOUSER | G15: BOURNS | H15: 3363P-1-201LF | I15: 0.85 | J15: =I15*E15 -> 1.7 | K15: 0.45 | L15: =K15*E15 -> 0.9
B16: 14 | C16: Connector, 3Pos | D16: CN1 | E16: 1 | F16: MOUSER | G16: MOLEX | H16: 26-60-4060 | I16: 0.25 | J16: =I16*E16 -> 0.25 | K16: 0.18 | L16: =K16*E16 -> 0.18
B17: 15 | C17: Connector, 6Pos | D17: CN2 | E17: 1 | F17: MOUSER | G17: MOLEX | H17: 26-60-4060 | I17: 0.65 | J17: =I17*E17 -> 0.65 | K17: 0.45 | L17: =K17*E17 -> 0.45
B18: 16 | C18: PCB | E18: 1 | I18: 0 | J18: =I18*E18 -> 0 | K18: 8 | L18: =K18*E18 -> 8
B19: 17 | C19: PCB Assembly | E19: 1 | I19: 0 | J19: =I19*E19 -> 0 | K19: 0 | L19: =K19*E19 -> 0
J20: =SUM(J3:J19) -> 51.74 | L20: =SUM(L3:L19) -> 47.31

Sheet OB-R IO Board
B2: ITEM | C2: DESCRIPTION | D2: DESIGNATOR | E2: VENDOR | F2: MANUFACTURER | G2: PART NUMBER | H2: PRICE | I2: QTY | J2: EXT
B3: 1 | C3: Resistor 24 Ohms 5% CF | D3: R8, R9, R10, R11 | E3: DIGIKEY | F3: Stackpole | G3: CF14JT2K20 | H3: 0.00729 | I3: 4 | J3: =I3*H3 -> 0.02916
B4: 2 | C4: Resistor 220 5% CF | D4: R1, R2, R4, R5, R6, R7 | E4: DIGIKEY | F4: Stackpole | G4: RC0603FR-07220RL | H4: 0.00729 | I4: 6 | J4: =I4*H4 -> 0.04374
B5: 3 | C5: Resistor 270 5% CF | D5: R3 | E5: DIGIKEY | F5: Stackpole | G5: RC0603FR-07270RL | H5: 0.00729 | I5: 1 | J5: =I5*H5 -> 0.00729
B6: 4 | C6: Capacitor 10nF C0G | D6: C2, C5 | E6: DIGIKEY | F6: Yageo | G6: ISHIDDEN=T | H6: 0.01 | I6: 2 | J6: =I6*H6 -> 0.02
B7: 5 | C7: Capacitor 0.1uF X7R | D7: C1, C3, C6 | E7: DIGIKEY | F7: Yageo | G7: C0805C104K3RACTU | H7: 0.01 | I7: 3 | J7: =I7*H7 -> 0.03
B8: 6 | C8: Capacitor 4.7uF Elec | D8: C4, C7 | E8: DIGIKEY | F8: Yageo | G8: C0805C104K3RACTU | H8: 0.01 | I8: 2 | J8: =I8*H8 -> 0.02
B9: 7 | C9: Diode, SOD-80 | D9: D1 | E9: DIGIKEY | F9: Fairchild | G9: LL4148 | H9: 0.01 | I9: 1 | J9: =I9*H9 -> 0.01
B10: 8 | C10: EMIFILTER | D10: F1, F2, F3, F4, F5, F6, F7, F8, F9, F10 | E10: DIGIKEY | F10: Murata | G10: NFE31PT222Z1E9L | H10: 0.26 | I10: 10 | J10: =I10*H10 -> 2.6
B11: 9 | C11: OptoIsolator | D11: IC1 | E11: DIGIKEY | F11: Lite-On | G11: PC900V0NSZ | H11: 0.416 | I11: 1 | J11: =I11*H11 -> 0.416
B12: 10 | C12: Logic Buffer | D12: IC2 | E12: DIGIKEY | F12: TI | G12: SN74LVC2G04DBVRG4 | H12: 0.3 | I12: 1 | J12: =I12*H12 -> 0.3
B13: 11 | C13: Connector, DIN5 | D13: J1, J2, J3 | E13: DIGIKEY | F13: Hosiden | G13: Generic (On Hand) | H13: 0 | I13: 3 | J13: =I13*H13 -> 0
B14: 12 | C14: USB Jack | D14: J4 | E14: DIGIKEY | F14: Generic | G14: 00174-001 | H14: 0.133 | I14: 1 | J14: =I14*H14 -> 0.133
... B19: 17 | C19: Assembly, OB-R I/O | D19: NA | E19: GOLD PHOENIX | F19: Gold Phoenix | G19: Assembly, OB-R I/O | H19: 3 | I19: 1 | J19: =I19*H19 -> 3
J20: =SUM(J3:J19) -> 9.63419

Sheet OB-R Enclosure
B2: ITEM | C2: DESCRIPTION | D2: VENDOR | E2: MANUFACTURER | F2: PART NUMBER | G2: PRICE | H2: QTY | I2: EXT
B3: 1 | C3: Enclosure | D3: JLF | E3: JLF | F3: 00254 | G3: 157.61 | H3: 1 | I3: =G3*H3 -> 157.61
B4: 2 | C4: Screenprinting, Front Panel | D4: Technical Screen | E4: Technical Screen Printing | F4: 00254_Screen | G4: 30 | H4: 1 | I4: =G4*H4 -> 30
B5: 3 | C5: Screw, M3x 6mm, PPH | D5: TBD | E5: NA | F5: TBD | G5: $0.05 | H5: 24 | I5: =G5*H5 -> 1.2
B6: 4 | C6: Screw, M3.5x10mm, Cap | D6: TBD | E6: NA | F6: TBD | G6: 0.25 | H6: 4 | I6: =G6*H6 -> 1
I7: =SUM(I3:I5) -> 188.81

Sheet Hardware
B2: ITEM | C2: DESCRIPTION | E2: QTY | F2: MANUFACTURER | G2: VENDOR | H2: PART NUMBER | I2: PRICE | J2: EXT
B3: 1 | C3: Control Knob | D3: NA | E3: 21 | F3: Selco/Sifam | G3: Selco/Sifam | H3: DRN110-006 BLK | I3: 0.35 | J3: =I3*E3 -> 7.35
C4: Control Knob | D4: NA | E4: *21 | F4: Selco/Sifam | G4: Thonk | H4: DRN110-006 BLK
C5: Control Knob | D5: NA | E5: 1 | F5: Selco/Sifam | G5: Selco/Sifam | H5: DR110-006 BLK
C6: Control Knob | D6: NA | E6: 1 | F6: Selco/Sifam | G6: Thonk | H6: DR110-006 BLK
C7: Cap, Control Knob | D7: NA | E7: 22 | F7: Selco/Sifam | G7: Selco/Sifam | H7: C110BLK
C8: Cap, Control Knob | D8: NA | E8: *22 | F8: Selco/Sifam | G8: Thonk | H8: C110BLK
B9: 2 | C9: Phone Jack, Stereo | E9: 1 | F9: Amphenol | G9: MOLEX | H9: TBD | I9: 0.85 | J9: =I9*E9 -> 0.85
B10: 5 | C10: Fan, 5V | E10: 1 | F10: Noctua | G10: TBD | H10: TBD | I10: 8 | J10: =I10*E10 -> 8
B11: 6 | C11: IEC Jack | E11: 1 | F11: TBD | G11: TBD | H11: TBD | I11: 1 | J11: =I11*E11 -> 1
B12: 7 | C12: IEC Power Cord | E12: 1 | F12: Generic | G12: Generic | H12: Generic | I12: 2 | J12: =I12*E12 -> 2

Sheet Packaging
B2: ITEM | C2: DESCRIPTION | D2: VENDOR | E2: PART NUMBER | F2: MANUFACTURER | G2: QTY | H2: PRICE | I2: EXT
B3: 1 | C3: Packaging, Box | D3: LA Custom Pack. | E3: OB-R Beauty Carton | F3: LA Custom Pack. | G3: 1 | H3: 5 | I3: =H3*G3 -> 5
B4: 2 | C4: Packaging, End Pads | D4: GBW | E4: OB-R End Pad | F4: GBW | G4: 2 | H4: 1 | I4: =H4*G4 -> 2
B5: 3 | C5: Manual, Quick Start | D5: Uprint | E5: TBD | F5: UPRINT | G5: 1 | H5: 1.5 | I5: =H5*G5 -> 1.5
B6: 4 | C6: Poly Bag, 4mil. 24" x 12" | D6: TBD | E6: TBD | F6: TBD | G6: 1 | H6: 0.45 | I6: =H6*G6 -> 0.45
B7: 5 | C7: Poly Bag, 2mil zip, 9" x 6" | D7: TBD | E7: TBD | F7: TBD | G7: 1 | H7: 0.15 | I7: =H7*G7 -> 0.15
I8: =SUM(I3:I7) -> 9.1
